Workbook

Sheet Summary
A1: STR DSCR Search: Summary of Top Picks
A2: As of 2026-10-18. Every number below is a live link (green) to the market tabs; change inputs there or on Assumptions.
A4: Market Tab | B4: Address | C4: City / ZIP | D4: Offer Price | E4: Stated Gross ($/yr) | F4: PITIA ($/mo) | G4: DSCR (gross) | H4: DSCR (lender haircut) | I4: Cash to Close | J4: Cash Flow Self-Managed ($/yr) | K4: Cash Flow Full PM ($/yr) | L4: Verdict
A5: Manatee-Sarasota | B5: ='Manatee-Sarasota'!$B$6 -> 8404 43rd Ave Terrace W | C5: ='Manatee-Sarasota'!$C$6 -> Bradenton 34209 | D5: ='Manatee-Sarasota'!$H$6 -> 560000 | E5: ='Manatee-Sarasota'!$K$6 -> 85000 | F5: ='Manatee-Sarasota'!$W$6 -> 4315.1404 | G5: ='Manatee-Sarasota'!$X$6 -> 1.641507 | H5: ='Manatee-Sarasota'!$Y$6 -> 1.3132056 | I5: ='Manatee-Sarasota'!$Z$6 -> 145600 | J5: ='Manatee-Sarasota'!$AD$6 -> 4668.3155 | K5: ='Manatee-Sarasota'!$AE$6 -> -12331.685 | L5: #1 OVERALL: write it. PropertyRadar: ~$516k loan (3% equity) and an exemption flag (possible homestead). Seller may not clear payoff at $560k + 3%; verify homestead, T12, FEMA, appraisal.
A6: Manatee-Sarasota | B6: ='Manatee-Sarasota'!$B$7 -> 5318 17th St W (duplex) | C6: ='Manatee-Sarasota'!$C$7 -> Bradenton 34207 | D6: ='Manatee-Sarasota'!$H$7 -> 460000 | E6: ='Manatee-Sarasota'!$K$7 -> 73000 | F6: ='Manatee-Sarasota'!$W$7 -> 3678.5082 | G6: ='Manatee-Sarasota'!$X$7 -> 1.6537501 | H6: ='Manatee-Sarasota'!$Y$7 -> 1.3230001 | I6: ='Manatee-Sarasota'!$Z$7 -> 133400 | J6: ='Manatee-Sarasota'!$AD$7 -> 4867.902 | K6: ='Manatee-Sarasota'!$AE$7 -> -9732.098 | L6: Backup: cheapest, STR + LTR hedge. Confirm legal duplex.
A7: Manatee-Sarasota | B7: ='Manatee-Sarasota'!$B$8 -> 2801 23rd Ave W ("Beachin' Escape") | C7: ='Manatee-Sarasota'!$C$8 -> Bradenton 34205 | D7: ='Manatee-Sarasota'!$H$8 -> 600000 | E7: ='Manatee-Sarasota'!$K$8 -> 89000 | F7: ='Manatee-Sarasota'!$W$8 -> 4569.7933 | G7: ='Manatee-Sarasota'!$X$8 -> 1.6229764 | H7: ='Manatee-Sarasota'!$Y$8 -> 1.2983811 | I7: ='Manatee-Sarasota'!$Z$8 -> 156000 | J7: ='Manatee-Sarasota'!$AD$8 -> 4692.4809 | K7: ='Manatee-Sarasota'!$AE$8 -> -13107.519 | L7: Best income record; appraisal + sq-ft risk. Aggressive offer only.
A8: Pinellas | B8: =Pinellas!$B$6 -> 12565 81st Ave | C8: =Pinellas!$C$6 -> Seminole 33776 | D8: =Pinellas!$H$6 -> 485000 | E8: =Pinellas!$K$6 -> 71000 | F8: =Pinellas!$W$6 -> 3878.0829 | G8: =Pinellas!$X$6 -> 1.5256679 | H8: =Pinellas!$Y$6 -> 1.2205343 | I8: =Pinellas!$Z$6 -> 140650 | J8: =Pinellas!$AD$6 -> -866.99462 | K8: =Pinellas!$AE$6 -> -15066.995 | L8: Best Pinellas: licensed since 2022. 'Estimated' $71k: get T12. Confirm Seminole license transfers.
A9: Pinellas | B9: =Pinellas!$B$7 -> 4000 46th St N | C9: =Pinellas!$C$7 -> St Petersburg 33714 | D9: =Pinellas!$H$7 -> 485000 | E9: =Pinellas!$K$7 -> 85000 | F9: =Pinellas!$W$7 -> 3878.0829 | G9: =Pinellas!$X$7 -> 1.8265039 | H9: =Pinellas!$Y$7 -> 1.4612031 | I9: =Pinellas!$Z$7 -> 140650 | J9: =Pinellas!$AD$7 -> 9913.0054 | K9: =Pinellas!$AE$7 -> -7086.9946 | L9: Highest yield, but <12 months history + jurisdiction (St. Pete vs Lealman) unconfirmed.
A10: Pinellas | B10: =Pinellas!$B$8 -> 341 Wertz Dr | C10: =Pinellas!$C$8 -> Largo 33771 | D10: =Pinellas!$H$8 -> 340000 | E10: =Pinellas!$K$8 -> 51000 | F10: =Pinellas!$W$8 -> 2942.8828 | G10: =Pinellas!$X$8 -> 1.4441621 | H10: =Pinellas!$Y$8 -> 1.1553297 | I10: =Pinellas!$Z$8 -> 98600 | J10: =Pinellas!$AD$8 -> -3244.5942 | K10: =Pinellas!$AE$8 -> -13444.594 | L10: Cheap Largo STR; history is pre-hurricane. Negotiable (257 DOM).
A11: Other SWFL Listings | B11: ='Other SWFL Listings'!$B$6 -> 326 NW 21st Ter | C11: ='Other SWFL Listings'!$C$6 -> Cape Coral 33993 | D11: ='Other SWFL Listings'!$H$6 -> 460000 | E11: ='Other SWFL Listings'!$K$6 -> 60000 | F11: ='Other SWFL Listings'!$W$6 -> 3755.1748 | G11: ='Other SWFL Listings'!$X$6 -> 1.3314959 | H11: ='Other SWFL Listings'!$Y$6 -> 1.0651967 | I11: ='Other SWFL Listings'!$Z$6 -> 133400 | J11: ='Other SWFL Listings'!$AD$6 -> -7862.098 | K11: ='Other SWFL Listings'!$AE$6 -> -19862.098 | L11: Only SWFL listing that clears after haircut; inland NW Cape, check utility assessment.
A12: Monroe (Keys) | B12: ='Monroe (Keys)'!$B$7 -> 500 Burton Dr #2212 (Ocean Pointe) | C12: ='Monroe (Keys)'!$C$7 -> Tavernier 33070 | D12: ='Monroe (Keys)'!$H$7 -> 625000 | E12: ='Monroe (Keys)'!$K$7 -> 100000 | F12: ='Monroe (Keys)'!$W$7 -> 5390.493 | G12: ='Monroe (Keys)'!$X$7 -> 1.5459316 | H12: ='Monroe (Keys)'!$Y$7 -> 1.2367453 | I12: ='Monroe (Keys)'!$Z$7 -> 181250 | J12: ='Monroe (Keys)'!$AD$7 -> 5114.0842 | K12: ='Monroe (Keys)'!$AE$7 -> -14885.916 | L12: Best Keys DSCR on paper, but $100k avg on an 826 sf condo is agent-owner marketing: statements first.
A13: Monroe (Keys) | B13: ='Monroe (Keys)'!$B$6 -> 1500 Ocean Bay Dr #E5 (Kawama Yacht Club) | C13: ='Monroe (Keys)'!$C$6 -> Key Largo 33037 | D13: ='Monroe (Keys)'!$H$6 -> 760000 | E13: ='Monroe (Keys)'!$K$6 -> 98980 | F13: ='Monroe (Keys)'!$W$6 -> 5940.0715 | G13: ='Monroe (Keys)'!$X$6 -> 1.3885916 | H13: ='Monroe (Keys)'!$Y$6 -> 1.1108733 | I13: ='Monroe (Keys)'!$Z$6 -> 220400 | J13: ='Monroe (Keys)'!$AD$6 -> -2266.2576 | K13: ='Monroe (Keys)'!$AE$6 -> -22062.258 | L13: Cleanest Keys income claim; nightly allowed. Stretch price: ~$220k cash at 25% down.
A15: Key takeaways
A16: - Buyer: 800 FICO, $150k earmarked + $550k brokerage + $60k checking. Recommended structure: 25% down, 3% seller credit to rate buydown.
A17: - Rates are placeholders (7.50 / 7.25 / 7.125% by LTV tier): overwrite on the Assumptions tab and every tab reflows.
A18: - Cleaning is not a cost (passed through to guests as a cleaning fee): use gross EXCLUDING guest-paid cleaning fees. Platform fees 10%. #1 nets ~+$4.7k/yr self-managed; a 10-15% co-host is about breakeven; full-service PM does not cash flow at today's rates.
A19: - Pinellas: nightly SFH STRs are legal mainly in unincorporated county (Certificate of Use), Largo, Indian Rocks Beach, Redington Beach. St. Pete, St. Pete Beach, Clearwater residential, Gulfport, Dunedin = 30-day+.
A20: - Other SWFL: Cape Coral Gulf-access canals (33904/33914) are the best alternative market; Charlotte Harbor canals and unincorporated East Naples next. Avoid Pasco, Citrus, Hernando, City of Naples.
A21: - Keys: under $950k, documented income is almost all condos in a few STR-legal complexes (Ocean Pointe, Kawama, Hawks Cay). Houses with transferable rental rights are $1M+; county/Islamorada permits don't transfer, Marathon/Key Colony Beach (weekly) are the house plays. Keys insurance and HOAs push PITIA ~40% above the mainland.
A22: - PropertyRadar pull (193 listed absentee-owned homes, 3 counties): nothing beats 8404 43rd Ave Ter W. Best screen is 216 SW 29th St, Cape Coral (needs ~$52k gross for DSCR 1.00 at list) but it has no rental history; the only house with STR evidence is 930 SW 37th Ter, Cape Coral (state vacation-rental license, no $ figures).
A23: - All income is seller-stated until verified with 12-24 months of platform payouts + tourist-tax filings.

Sheet Assumptions
B1: STR / Seasonal DSCR Model: Assumptions
B2: As of 2026-10-18. Blue = input you can change. Yellow = key lever. Black = formula. Green = pulled from another tab.
B4: BUYER | C4: Value | I4: Note / source
B5: Credit score (FICO) | C5: 800 | I5: Per broker; top DSCR pricing tier.
B6: Cash earmarked for down + closing | C6: 150000 | I6: Per broker.
B7: Brokerage (reserves / extra down) | C7: 550000 | I7: Per broker. CPA: check capital gains before liquidating.
B8: Checking (EMD) | C8: 60000 | I8: Per broker. Earnest money 3-5% to compete.
B10: LOAN TERMS (DSCR) | C10: Value | I10: Note / source
B11: Rate at LTV > 75% (i.e., 80% LTV) | C11: 0.075 | I11: Placeholder for 800 FICO STR DSCR. Overwrite with live rate sheet.
B12: Rate at LTV > 70% to 75% | C12: 0.0725 | I12: Placeholder. Overwrite with live rate sheet.
B13: Rate at LTV <= 70% | C13: 0.07125 | I13: Placeholder. Overwrite with live rate sheet.
B14: Amortization (months) | C14: 360 | I14: 30-year fixed.
B15: Default down payment % | C15: 0.25 | I15: Recommended 25% (rate tier + DSCR + cash flow). Each candidate row can override.
B16: Closing costs (% of price) | C16: 0.04 | I16: Points/fees, FL doc stamps 0.35% + intangible 0.2% of loan, title, 12-mo prepaid insurance, escrow.
B17: Reserves required (months PITIA) | C17: 6 | I17: Covered by brokerage; shown for lender sizing only.
B18: Lender income haircut (counted share of gross) | C18: 0.8 | I18: Many STR DSCR lenders count ~80% of gross or T12 net of mgmt. Use DSCR (haircut) column to qualify.
B19: Default base insurance ($/yr): HO + wind + $1M STR liability | C19: 7000 | I19: Mainland CBS home ~$500k. Per-county overrides in the county table below (e.g., Monroe/Keys).
B21: FLOOD INSURANCE BY FEMA ZONE ($/yr) | C21: $/yr | I21: Note / source
B22: X | C22: 1000 | I22: Citizens requires flood on all wind policies by 1/1/2027, including X zones.
B23: AE | C23: 4500 | I23: NFIP Risk Rating 2.0 est.; elevation certificate drives price.
B24: VE | C24: 9000 | I24: Coastal high-hazard; avoid for this buyer.
B25: Unknown | C25: 2000 | I25: Placeholder until FEMA zone verified.
B27: BY COUNTY: PROPERTY TAX (% of price, non-homestead) + BASE INSURANCE | C27: Tax rate | D27: Base ins. $/yr | I27: Note / source
B28: Manatee | C28: 0.015 | D28: =$C$19 -> 7000 | I28: Unincorporated ~13.3 mills (2025) + city + non-ad valorem; reset to purchase price.
B29: Sarasota | C29: 0.0135 | D29: =$C$19 -> 7000 | I29: 11.47 mills countywide (2025); City of Sarasota ~14.9 mills.
B30: Pinellas | C30: 0.016 | D30: =$C$19 -> 7000 | I30: Beach towns ~15.8-16.6 mills (2025) + non-ad valorem; ~1.4-1.7% of price est.
B31: Lee | C31: 0.017 | D31: =$C$19 -> 7000 | I31: Placeholder: Cape Coral/Fort Myers ~16-19 mills; North Cape utility assessments extra (~$3.4k/yr).
B32: Charlotte | C32: 0.0165 | D32: =$C$19 -> 7000 | I32: Placeholder.
B33: Collier | C33: 0.014 | D33: =$C$19 -> 7000 | I33: Placeholder: lowest millage on the coast; ~1.4-1.5% incl. non-ad valorem.
B34: Monroe | C34: 0.0095 | D34: 8000 | I34: Keys: ~7.9-9.0 mills (2026) -> 0.70-0.90% of price + $800-1,200/yr non-ad valorem (solid waste, wastewater). Base ins. = wind + non-wind STR policy for an elevated CBS house; flood by zone on top (~$12.5k AE total). Ground-level pre-FIRM: override ~$20k+. Condos: per-row HO-6 override.
B36: OPERATING PROFILE | C36: Mgmt | D36: Platform | E36: Cleaning | F36: Maint/Supplies | G36: CapEx | H36: Non-mgmt total | I36: Note / source
B37: STR | C37: 0.2 | D37: 0.1 | E37: 0 | F37: 0.08 | G37: 0.05 | H37: =SUM(D37:G37) -> 0.23 | I37: Nightly/weekly. Full-service PM 18-30% locally; Airbnb host-only fee 15.5% (blended 10%); cleaning = 0: passed through to guests as a cleaning fee. Use gross EXCLUDING guest-paid cleaning fees.
B38: Seasonal | C38: 0.12 | D38: 0.02 | E38: 0 | F38: 0.06 | G38: 0.05 | H38: =SUM(D38:G38) -> 0.13 | I38: 30-day+ furnished (snowbird Jan-Apr, travel nurses, insurance displacement). Fewer turns.
B40: FIXED OPERATING COSTS ($/yr) | C40: $/yr | I40: Note / source
B41: Utilities (power, water, internet, streaming) | C41: 6000 | I41: Owner-paid in furnished rentals.
B42: Pool + lawn + pest (with pool) | C42: 3000
B43: Lawn + pest (no pool) | C43: 1200

Sheet Manatee-Sarasota
A1: Manatee + Sarasota County: STR / Seasonal Candidates with Documented Income
A2: Active as of 2026-10-18. Screened ~600 listings across Zillow (14 keyword sweeps), Redfin, brokerages and STR marketplaces. Yellow rows = recommended.
A3: Edit blue cells (Offer Price, Seller Credit %, Down Pmt %, Income, Flood Zone, Ins Override) to rerun. Ins Override (blank = county base + flood) is for condos with master wind/flood policies. Qualify on DSCR (lender haircut) >= 1.00; >= 1.15 preferred. Income is seller-stated until verified with platform payout reports.
A5: Rank | B5: Address | C5: City / ZIP | D5: County | E5: Type | F5: Bd/Ba/SqFt/Yr | G5: List Price | H5: Offer Price | I5: Seller Credit % | J5: Down Pmt % | K5: Stated Gross Income ($/yr) | L5: Income Basis (seller-stated) | M5: Flood Zone | N5: Pool | O5: HOA ($/mo) | P5: Ins Override ($/yr) | Q5: Profile | R5: Loan Amount | S5: Rate | T5: P&I ($/mo) | U5: Taxes ($/mo) | V5: Ins + Flood ($/mo) | W5: PITIA ($/mo) | X5: DSCR (gross) | Y5: DSCR (lender haircut) | Z5: Cash to Close | AA5: Reserves (6 mo) | AB5: Opex excl. Mgmt ($/yr) | AC5: Mgmt ($/yr) | AD5: Cash Flow Self-Managed ($/yr) | AE5: Cash Flow Full PM ($/yr) | AF5: Gross Yield | AG5: Cap Rate (w/ PM) | AH5: Last Sale | AI5: DOM | AJ5: Key Risks / Notes | AK5: Listing Link
A6: 1 | B6: 8404 43rd Ave Terrace W | C6: Bradenton 34209 | D6: Manatee | E6: SFR | F6: 4/2 / 1,430 / 1978 | G6: 584900 | H6: 560000 | I6: 0.03 | J6: =Assumptions!$C$15 -> 0.25 | K6: 85000 | L6: "almost $85,000 in gross revenue over the past 12 months" (T12) | M6: Unknown | N6: Y | O6: 0 | Q6: STR | R6: =H6*(1-J6) -> 420000 | S6: =IF((1-J6)>0.75,Assumptions!$C$11,IF((1-J6)>0.7,Assumptions!$C$12,Assumptions!$C$13)) -> 0.0725 | T6: =PMT(S6/12,Assumptions!$C$14,-R6) -> 2865.1404 | U6: =H6*INDEX(Assumptions!$C$28:$C$34,MATCH(D6,Assumptions!$B$28:$B$34,0))/12 -> 700 | V6: =IF(ISNUMBER(P6),P6,INDEX(Assumptions!$D$28:$D$34,MATCH(D6,Assumptions!$B$28:$B$34,0))+INDEX(Assumptions!$C$22:$C$25,MATCH(M6,Assumptions!$B$22:$B$25,0)))/12 -> 750 | W6: =T6+U6+V6+O6 -> 4315.1404 | X6: =IFERROR(K6/12/W6,0) -> 1.641507 | Y6: =IFERROR(K6*Assumptions!$C$18/12/W6,0) -> 1.3132056 | Z6: =H6*J6+H6*(Assumptions!$C$16-I6) -> 145600 | AA6: =W6*Assumptions!$C$17 -> 25890.842 | AB6: =K6*INDEX(Assumptions!$H$37:$H$38,MATCH(Q6,Assumptions!$B$37:$B$38,0))+Assumptions!$C$41+IF(N6="Y",Assumptions!$C$42,Assumptions!$C$43) -> 28550 | AC6: =K6*INDEX(Assumptions!$C$37:$C$38,MATCH(Q6,Assumptions!$B$37:$B$38,0)) -> 17000 | AD6: =K6-AB6-W6*12 -> 4668.3155 | AE6: =AD6-AC6 -> -12331.685 | AF6: =IFERROR(K6/H6,0) -> 0.15178571 | AG6: =IFERROR((K6-AB6-AC6)/H6,0) -> 0.070446429 | AH6: $595,000 (Aug 2023) | AI6: 21 | AJ6: Heated pool + spa, no HOA, turnkey; full 2021 reno (roof/HVAC/windows/plumbing/electric). First Street flood 7/10; neighbor parcel AE/X: get FEMA zone + elevation cert + CLUE. Featured in national STR newsletter 9/29: move fast. Uninc. Manatee: nightly legal. | AK6: Zillow
A7: 2 | B7: 5318 17th St W (duplex) | C7: Bradenton 34207 | D7: Manatee | E7: Duplex | F7: 2 units / 1,740 / 1971 | G7: 475000 | H7: 460000 | I7: 0 | J7: =Assumptions!$C$15 -> 0.25 | K7: 73000 | L7: Unit B Airbnb "over $53,000 in 2025" + Unit A LTR (est. ~$20k/yr; rent not stated) | M7: Unknown | N7: N | O7: 0 | Q7: STR | R7: =H7*(1-J7) -> 345000 | S7: =IF((1-J7)>0.75,Assumptions!$C$11,IF((1-J7)>0.7,Assumptions!$C$12,Assumptions!$C$13)) -> 0.0725 | T7: =PMT(S7/12,Assumptions!$C$14,-R7) -> 2353.5082 | U7: =H7*INDEX(Assumptions!$C$28:$C$34,MATCH(D7,Assumptions!$B$28:$B$34,0))/12 -> 575 | V7: =IF(ISNUMBER(P7),P7,INDEX(Assumptions!$D$28:$D$34,MATCH(D7,Assumptions!$B$28:$B$34,0))+INDEX(Assumptions!$C$22:$C$25,MATCH(M7,Assumptions!$B$22:$B$25,0)))/12 -> 750 | W7: =T7+U7+V7+O7 -> 3678.5082 | X7: =IFERROR(K7/12/W7,0) -> 1.6537501 | Y7: =IFERROR(K7*Assumptions!$C$18/12/W7,0) -> 1.3230001 | Z7: =H7*J7+H7*(Assumptions!$C$16-I7) -> 133400 | AA7: =W7*Assumptions!$C$17 -> 22071.049 | AB7: =K7*INDEX(Assumptions!$H$37:$H$38,MATCH(Q7,Assumptions!$B$37:$B$38,0))+Assumptions!$C$41+IF(N7="Y",Assumptions!$C$42,Assumptions!$C$43) -> 23990 | AC7: =K7*INDEX(Assumptions!$C$37:$C$38,MATCH(Q7,Assumptions!$B$37:$B$38,0)) -> 14600 | AD7: =K7-AB7-W7*12 -> 4867.902 | AE7: =AD7-AC7 -> -9732.098 | AF7: =IFERROR(K7/H7,0) -> 0.15869565 | AG7: =IFERROR((K7-AB7-AC7)/H7,0) -> 0.074804348 | AH7: $420,000 (Apr 2024) | AI7: 14 | AJ7: Zoned RSF-6 and listed as SFR: confirm legal nonconforming duplex. Confirm lender blends STR + LTR income. Opex model applies STR costs to all income (conservative). | AK7: Zillow
A8: 3 | B8: 2801 23rd Ave W ("Beachin' Escape") | C8: Bradenton 34205 | D8: Manatee | E8: SFR | F8: 4/2 / 1,906 (PR 1,564) / 1968 | G8: 645000 | H8: 600000 | I8: 0.03 | J8: =Assumptions!$C$15 -> 0.25 | K8: 89000 | L8: "$89,000 gross vacation-rental revenue in 2025"; "$91,500 in booked 2026 revenue" | M8: Unknown | N8: Y | O8: 0 | Q8: STR | R8: =H8*(1-J8) -> 450000 | S8: =IF((1-J8)>0.75,Assumptions!$C$11,IF((1-J8)>0.7,Assumptions!$C$12,Assumptions!$C$13)) -> 0.0725 | T8: =PMT(S8/12,Assumptions!$C$14,-R8) -> 3069.7933 | U8: =H8*INDEX(Assumptions!$C$28:$C$34,MATCH(D8,Assumptions!$B$28:$B$34,0))/12 -> 750 | V8: =IF(ISNUMBER(P8),P8,INDEX(Assumptions!$D$28:$D$34,MATCH(D8,Assumptions!$B$28:$B$34,0))+INDEX(Assumptions!$C$22:$C$25,MATCH(M8,Assumptions!$B$22:$B$25,0)))/12 -> 750 | W8: =T8+U8+V8+O8 -> 4569.7933 | X8: =IFERROR(K8/12/W8,0) -> 1.6229764 | Y8: =IFERROR(K8*Assumptions!$C$18/12/W8,0) -> 1.2983811 | Z8: =H8*J8+H8*(Assumptions!$C$16-I8) -> 156000 | AA8: =W8*Assumptions!$C$17 -> 27418.76 | AB8: =K8*INDEX(Assumptions!$H$37:$H$38,MATCH(Q8,Assumptions!$B$37:$B$38,0))+Assumptions!$C$41+IF(N8="Y",Assumptions!$C$42,Assumptions!$C$43) -> 29470 | AC8: =K8*INDEX(Assumptions!$C$37:$C$38,MATCH(Q8,Assumptions!$B$37:$B$38,0)) -> 17800 | AD8: =K8-AB8-W8*12 -> 4692.4809 | AE8: =AD8-AC8 -> -13107.519 | AF8: =IFERROR(K8/H8,0) -> 0.14833333 | AG8: =IFERROR((K8-AB8-AC8)/H8,0) -> 0.06955 | AH8: $474,000 (Mar 2024) | AI8: 23 | AJ8: Strongest track record. Appraisal risk: +36% vs 2024 purchase; public record 1,564 sf vs 1,906 marketed (possible unpermitted space); contract fell through 9/27-9/29: ask why. Listed by Locals Property Mgmt. | AK8: Zillow
A9: 4 | B9: 2245 Bahia Vista St (duplex) | C9: Sarasota 34239 | D9: Sarasota | E9: Duplex | F9: 2/1 + 1/1 / 1,652 / 1936 | G9: 475000 | H9: 455000 | I9: 0 | J9: =Assumptions!$C$15 -> 0.25 | K9: 60000 | L9: "currently generates more than $60,000 annually"; income + expenses available | M9: X | N9: N | O9: 0 | Q9: STR | R9: =H9*(1-J9) -> 341250 | S9: =IF((1-J9)>0.75,Assumptions!$C$11,IF((1-J9)>0.7,Assumptions!$C$12,Assumptions!$C$13)) -> 0.0725 | T9: =PMT(S9/12,Assumptions!$C$14,-R9) -> 2327.9266 | U9: =H9*INDEX(Assumptions!$C$28:$C$34,MATCH(D9,Assumptions!$B$28:$B$34,0))/12 -> 511.875 | V9: =IF(ISNUMBER(P9),P9,INDEX(Assumptions!$D$28:$D$34,MATCH(D9,Assumptions!$B$28:$B$34,0))+INDEX(Assumptions!$C$22:$C$25,MATCH(M9,Assumptions!$B$22:$B$25,0)))/12 -> 666.66667 | W9: =T9+U9+V9+O9 -> 3506.4682 | X9: =IFERROR(K9/12/W9,0) -> 1.4259362 | Y9: =IFERROR(K9*Assumptions!$C$18/12/W9,0) -> 1.140749 | Z9: =H9*J9+H9*(Assumptions!$C$16-I9) -> 131950 | AA9: =W9*Assumptions!$C$17 -> 21038.809 | AB9: =K9*INDEX(Assumptions!$H$37:$H$38,MATCH(Q9,Assumptions!$B$37:$B$38,0))+Assumptions!$C$41+IF(N9="Y",Assumptions!$C$42,Assumptions!$C$43) -> 21000 | AC9: =K9*INDEX(Assumptions!$C$37:$C$38,MATCH(Q9,Assumptions!$B$37:$B$38,0)) -> 12000 | AD9: =K9-AB9-W9*12 -> -3077.6187 | AE9: =AD9-AC9 -> -15077.619 | AF9: =IFERROR(K9/H9,0) -> 0.13186813 | AG9: =IFERROR((K9-AB9-AC9)/H9,0) -> 0.059340659 | AH9: Listed $545k (May 2025) -> $475k | AI9: 78 | AJ9: City of Sarasota 7-night minimum + annual registration/inspection. 1936 build: 4-point/insurance risk. 2025 roof. Land-value upside. | AK9: Zillow
A10: 5 | B10: 1415 36th St W ("Bamboo Lagoon") | C10: Bradenton 34205 | D10: Manatee | E10: SFR | F10: 3/2 / 1,176 / 1972 | G10: 474999 | H10: 474999 | I10: 0 | J10: =Assumptions!$C$15 -> 0.25 | K10: 54000 | L10: "$45,200 gross revenue YTD at 86% occupancy"; 4.99 stars / 82 reviews; bookings convey | M10: X | N10: Y | O10: 0 | Q10: STR | R10: =H10*(1-J10) -> 356249.25 | S10: =IF((1-J10)>0.75,Assumptions!$C$11,IF((1-J10)>0.7,Assumptions!$C$12,Assumptions!$C$13)) -> 0.0725 | T10: =PMT(S10/12,Assumptions!$C$14,-R10) -> 2430.2479 | U10: =H10*INDEX(Assumptions!$C$28:$C$34,MATCH(D10,Assumptions!$B$28:$B$34,0))/12 -> 593.74875 | V10: =IF(ISNUMBER(P10),P10,INDEX(Assumptions!$D$28:$D$34,MATCH(D10,Assumptions!$B$28:$B$34,0))+INDEX(Assumptions!$C$22:$C$25,MATCH(M10,Assumptions!$B$22:$B$25,0)))/12 -> 666.66667 | W10: =T10+U10+V10+O10 -> 3690.6633 | X10: =IFERROR(K10/12/W10,0) -> 1.219293 | Y10: =IFERROR(K10*Assumptions!$C$18/12/W10,0) -> 0.97543442 | Z10: =H10*J10+H10*(Assumptions!$C$16-I10) -> 137749.71 | AA10: =W10*Assumptions!$C$17 -> 22143.98 | AB10: =K10*INDEX(Assumptions!$H$37:$H$38,MATCH(Q10,Assumptions!$B$37:$B$38,0))+Assumptions!$C$41+IF(N10="Y",Assumptions!$C$42,Assumptions!$C$43) -> 21420 | AC10: =K10*INDEX(Assumptions!$C$37:$C$38,MATCH(Q10,Assumptions!$B$37:$B$38,0)) -> 10800 | AD10: =K10-AB10-W10*12 -> -11707.96 | AE10: =AD10-AC10 -> -22507.96 | AF10: =IFERROR(K10/H10,0) -> 0.11368445 | AG10: =IFERROR((K10-AB10-AC10)/H10,0) -> 0.045852728 | AH10: $349,000 (Dec 2024) | AI10: 18 | AJ10: Appraisal risk: +36% vs Dec 2024 purchase. Pool likely added after purchase. | AK10: Zillow
A11: 6 | B11: 3409 18th Avenue Dr W | C11: Bradenton 34205 | D11: Manatee | E11: SFR | F11: 3/2 / 1,644 / 1971 | G11: 529000 | H11: 515000 | I11: 0 | J11: =Assumptions!$C$15 -> 0.25 | K11: 60000 | L11: "over $53,000 in bookings so far this year" | M11: Unknown | N11: Y | O11: 0 | Q11: STR | R11: =H11*(1-J11) -> 386250 | S11: =IF((1-J11)>0.75,Assumptions!$C$11,IF((1-J11)>0.7,Assumptions!$C$12,Assumptions!$C$13)) -> 0.0725 | T11: =PMT(S11/12,Assumptions!$C$14,-R11) -> 2634.9059 | U11: =H11*INDEX(Assumptions!$C$28:$C$34,MATCH(D11,Assumptions!$B$28:$B$34,0))/12 -> 643.75 | V11: =IF(ISNUMBER(P11),P11,INDEX(Assumptions!$D$28:$D$34,MATCH(D11,Assumptions!$B$28:$B$34,0))+INDEX(Assumptions!$C$22:$C$25,MATCH(M11,Assumptions!$B$22:$B$25,0)))/12 -> 750 | W11: =T11+U11+V11+O11 -> 4028.6559 | X11: =IFERROR(K11/12/W11,0) -> 1.2411087 | Y11: =IFERROR(K11*Assumptions!$C$18/12/W11,0) -> 0.99288699 | Z11: =H11*J11+H11*(Assumptions!$C$16-I11) -> 149350 | AA11: =W11*Assumptions!$C$17 -> 24171.935 | AB11: =K11*INDEX(Assumptions!$H$37:$H$38,MATCH(Q11,Assumptions!$B$37:$B$38,0))+Assumptions!$C$41+IF(N11="Y",Assumptions!$C$42,Assumptions!$C$43) -> 22800 | AC11: =K11*INDEX(Assumptions!$C$37:$C$38,MATCH(Q11,Assumptions!$B$37:$B$38,0)) -> 12000 | AD11: =K11-AB11-W11*12 -> -11143.871 | AE11: =AD11-AC11 -> -23143.871 | AF11: =IFERROR(K11/H11,0) -> 0.11650485 | AG11: =IFERROR((K11-AB11-AC11)/H11,0) -> 0.048932039 | AH11: $525,000 (Jun 2024) | AI11: 58 | AJ11: Two price cuts ($550k -> $529k). Roof 2024. City of Bradenton zoning (R1C): STR certificate required. | AK11: Zillow
A12: 7 | B12: 2142 Waldemere St | C12: Sarasota 34239 | D12: Sarasota | E12: SFR | F12: 3/2 / 1,170 / 1952 | G12: 524900 | H12: 505000 | I12: 0 | J12: =Assumptions!$C$15 -> 0.25 | K12: 50157 | L12: "$50,157 gross rental revenue in 2025 and $55,323 in 2024"; Jan-Apr ~$8k/mo | M12: X | N12: N | O12: 0 | Q12: STR | R12: =H12*(1-J12) -> 378750 | S12: =IF((1-J12)>0.75,Assumptions!$C$11,IF((1-J12)>0.7,Assumptions!$C$12,Assumptions!$C$13)) -> 0.0725 | T12: =PMT(S12/12,Assumptions!$C$14,-R12) -> 2583.7427 | U12: =H12*INDEX(Assumptions!$C$28:$C$34,MATCH(D12,Assumptions!$B$28:$B$34,0))/12 -> 568.125 | V12: =IF(ISNUMBER(P12),P12,INDEX(Assumptions!$D$28:$D$34,MATCH(D12,Assumptions!$B$28:$B$34,0))+INDEX(Assumptions!$C$22:$C$25,MATCH(M12,Assumptions!$B$22:$B$25,0)))/12 -> 666.66667 | W12: =T12+U12+V12+O12 -> 3818.5343 | X12: =IFERROR(K12/12/W12,0) -> 1.0945954 | Y12: =IFERROR(K12*Assumptions!$C$18/12/W12,0) -> 0.8756763 | Z12: =H12*J12+H12*(Assumptions!$C$16-I12) -> 146450 | AA12: =W12*Assumptions!$C$17 -> 22911.206 | AB12: =K12*INDEX(Assumptions!$H$37:$H$38,MATCH(Q12,Assumptions!$B$37:$B$38,0))+Assumptions!$C$41+IF(N12="Y",Assumptions!$C$42,Assumptions!$C$43) -> 18736.11 | AC12: =K12*INDEX(Assumptions!$C$37:$C$38,MATCH(Q12,Assumptions!$B$37:$B$38,0)) -> 10031.4 | AD12: =K12-AB12-W12*12 -> -14401.522 | AE12: =AD12-AC12 -> -24432.922 | AF12: =IFERROR(K12/H12,0) -> 0.099320792 | AG12: =IFERROR((K12-AB12-AC12)/H12,0) -> 0.042355426 | AH12: $440,000 (Jun 2023) | AI12: 16 | AJ12: City 7-night min. "Previously operated": confirm still active. Sold as-is; metal roof 2026. | AK12: Zillow
A13: 8 | B13: 7405 12th Ave W | C13: Bradenton 34209 | D13: Manatee | E13: SFR | F13: 2/2 / 1,469 / 1973 | G13: 550000 | H13: 530000 | I13: 0 | J13: =Assumptions!$C$15 -> 0.25 | K13: 48000 | L13: "just under a year... nearly $45,000 in rental income" | M13: Unknown | N13: Y | O13: 8 | Q13: STR | R13: =H13*(1-J13) -> 397500 | S13: =IF((1-J13)>0.75,Assumptions!$C$11,IF((1-J13)>0.7,Assumptions!$C$12,Assumptions!$C$13)) -> 0.0725 | T13: =PMT(S13/12,Assumptions!$C$14,-R13) -> 2711.6507 | U13: =H13*INDEX(Assumptions!$C$28:$C$34,MATCH(D13,Assumptions!$B$28:$B$34,0))/12 -> 662.5 | V13: =IF(ISNUMBER(P13),P13,INDEX(Assumptions!$D$28:$D$34,MATCH(D13,Assumptions!$B$28:$B$34,0))+INDEX(Assumptions!$C$22:$C$25,MATCH(M13,Assumptions!$B$22:$B$25,0)))/12 -> 750 | W13: =T13+U13+V13+O13 -> 4132.1507 | X13: =IFERROR(K13/12/W13,0) -> 0.9680189 | Y13: =IFERROR(K13*Assumptions!$C$18/12/W13,0) -> 0.77441512 | Z13: =H13*J13+H13*(Assumptions!$C$16-I13) -> 153700 | AA13: =W13*Assumptions!$C$17 -> 24792.904 | AB13: =K13*INDEX(Assumptions!$H$37:$H$38,MATCH(Q13,Assumptions!$B$37:$B$38,0))+Assumptions!$C$41+IF(N13="Y",Assumptions!$C$42,Assumptions!$C$43) -> 20040 | AC13: =K13*INDEX(Assumptions!$C$37:$C$38,MATCH(Q13,Assumptions!$B$37:$B$38,0)) -> 9600 | AD13: =K13-AB13-W13*12 -> -21625.809 | AE13: =AD13-AC13 -> -31225.809 | AF13: =IFERROR(K13/H13,0) -> 0.090566038 | AG13: =IFERROR((K13-AB13-AC13)/H13,0) -> 0.034641509 | AH13: $75,000 (2016) | AI13: 12 | AJ13: <12 months history; 2BR. Solar 'majority owned': check lien on remainder. | AK13: Zillow
A14: 9 | B14: 2705 2nd Ave W | C14: Bradenton 34205 | D14: Manatee | E14: SFR | F14: 2/1 / 1,198 / 1925 | G14: 385000 | H14: 360000 | I14: 0 | J14: =Assumptions!$C$15 -> 0.25 | K14: 40000 | L14: "currently brings in $40K/year in gross income" | M14: X | N14: N | O14: 0 | Q14: STR | R14: =H14*(1-J14) -> 270000 | S14: =IF((1-J14)>0.75,Assumptions!$C$11,IF((1-J14)>0.7,Assumptions!$C$12,Assumptions!$C$13)) -> 0.0725 | T14: =PMT(S14/12,Assumptions!$C$14,-R14) -> 1841.876 | U14: =H14*INDEX(Assumptions!$C$28:$C$34,MATCH(D14,Assumptions!$B$28:$B$34,0))/12 -> 450 | V14: =IF(ISNUMBER(P14),P14,INDEX(Assumptions!$D$28:$D$34,MATCH(D14,Assumptions!$B$28:$B$34,0))+INDEX(Assumptions!$C$22:$C$25,MATCH(M14,Assumptions!$B$22:$B$25,0)))/12 -> 666.66667 | W14: =T14+U14+V14+O14 -> 2958.5426 | X14: =IFERROR(K14/12/W14,0) -> 1.1266809 | Y14: =IFERROR(K14*Assumptions!$C$18/12/W14,0) -> 0.90134468 | Z14: =H14*J14+H14*(Assumptions!$C$16-I14) -> 104400 | AA14: =W14*Assumptions!$C$17 -> 17751.256 | AB14: =K14*INDEX(Assumptions!$H$37:$H$38,MATCH(Q14,Assumptions!$B$37:$B$38,0))+Assumptions!$C$41+IF(N14="Y",Assumptions!$C$42,Assumptions!$C$43) -> 16400 | AC14: =K14*INDEX(Assumptions!$C$37:$C$38,MATCH(Q14,Assumptions!$B$37:$B$38,0)) -> 8000 | AD14: =K14-AB14-W14*12 -> -11902.511 | AE14: =AD14-AC14 -> -19902.511 | AF14: =IFERROR(K14/H14,0) -> 0.11111111 | AG14: =IFERROR((K14-AB14-AC14)/H14,0) -> 0.043333333 | AH14: $240,000 (May 2021) | AI14: 214 | AJ14: 377 cumulative DOM: very negotiable. 1BA, 1925: insurance. City of Bradenton certificate. | AK14: Zillow
A15: 10 | B15: 4711 Hollingsworth Ave (3 units) | C15: Sarasota 34233 | D15: Sarasota | E15: Triplex | F15: 3 furnished units / 1,696 / 1981 | G15: 655000 | H15: 655000 | I15: 0 | J15: =Assumptions!$C$15 -> 0.25 | K15: 102000 | L15: "averaging approximately $102,000 in annual revenue during 2024-2025"; OM available | M15: Unknown | N15: N | O15: 0 | Q15: Seasonal | R15: =H15*(1-J15) -> 491250 | S15: =IF((1-J15)>0.75,Assumptions!$C$11,IF((1-J15)>0.7,Assumptions!$C$12,Assumptions!$C$13)) -> 0.0725 | T15: =PMT(S15/12,Assumptions!$C$14,-R15) -> 3351.191 | U15: =H15*INDEX(Assumptions!$C$28:$C$34,MATCH(D15,Assumptions!$B$28:$B$34,0))/12 -> 736.875 | V15: =IF(ISNUMBER(P15),P15,INDEX(Assumptions!$D$28:$D$34,MATCH(D15,Assumptions!$B$28:$B$34,0))+INDEX(Assumptions!$C$22:$C$25,MATCH(M15,Assumptions!$B$22:$B$25,0)))/12 -> 750 | W15: =T15+U15+V15+O15 -> 4838.066 | X15: =IFERROR(K15/12/W15,0) -> 1.7569004 | Y15: =IFERROR(K15*Assumptions!$C$18/12/W15,0) -> 1.4055203 | Z15: =H15*J15+H15*(Assumptions!$C$16-I15) -> 189950 | AA15: =W15*Assumptions!$C$17 -> 29028.396 | AB15: =K15*INDEX(Assumptions!$H$37:$H$38,MATCH(Q15,Assumptions!$B$37:$B$38,0))+Assumptions!$C$41+IF(N15="Y",Assumptions!$C$42,Assumptions!$C$43) -> 20460 | AC15: =K15*INDEX(Assumptions!$C$37:$C$38,MATCH(Q15,Assumptions!$B$37:$B$38,0)) -> 12240 | AD15: =K15-AB15-W15*12 -> 23483.208 | AE15: =AD15-AC15 -> 11243.208 | AF15: =IFERROR(K15/H15,0) -> 0.15572519 | AG15: =IFERROR((K15-AB15-AC15)/H15,0) -> 0.10580153 | AH15: $350,000 (Feb 2022) | AI15: 5 | AJ15: Unincorporated Sarasota County: <30-day banned in this zoning -> 30-day+ model. Zestimate ~$325k: will NOT appraise for DSCR. Seller financing offered: pursue only on seller terms. | AK15: Zillow
A16: 11 | B16: 4440 47th Ave W #102 (Shorewalk condo) | C16: Bradenton 34210 | D16: Manatee | E16: Condo | F16: 2/2 / 1,174 / 1989 | G16: 279000 | H16: 279000 | I16: 0 | J16: =Assumptions!$C$15 -> 0.25 | K16: 44000 | L16: "Gross rental earnings for January-June are $29,300"; 4.96 stars | M16: Unknown | N16: N | O16: 477 | Q16: STR | R16: =H16*(1-J16) -> 209250 | S16: =IF((1-J16)>0.75,Assumptions!$C$11,IF((1-J16)>0.7,Assumptions!$C$12,Assumptions!$C$13)) -> 0.0725 | T16: =PMT(S16/12,Assumptions!$C$14,-R16) -> 1427.4539 | U16: =H16*INDEX(Assumptions!$C$28:$C$34,MATCH(D16,Assumptions!$B$28:$B$34,0))/12 -> 348.75 | V16: =IF(ISNUMBER(P16),P16,INDEX(Assumptions!$D$28:$D$34,MATCH(D16,Assumptions!$B$28:$B$34,0))+INDEX(Assumptions!$C$22:$C$25,MATCH(M16,Assumptions!$B$22:$B$25,0)))/12 -> 750 | W16: =T16+U16+V16+O16 -> 3003.2039 | X16: =IFERROR(K16/12/W16,0) -> 1.2209183 | Y16: =IFERROR(K16*Assumptions!$C$18/12/W16,0) -> 0.97673467 | Z16: =H16*J16+H16*(Assumptions!$C$16-I16) -> 80910 | AA16: =W16*Assumptions!$C$17 -> 18019.223 | AB16: =K16*INDEX(Assumptions!$H$37:$H$38,MATCH(Q16,Assumptions!$B$37:$B$38,0))+Assumptions!$C$41+IF(N16="Y",Assumptions!$C$42,Assumptions!$C$43) -> 17320 | AC16: =K16*INDEX(Assumptions!$C$37:$C$38,MATCH(Q16,Assumptions!$B$37:$B$38,0)) -> 8800 | AD16: =K16-AB16-W16*12 -> -9358.4464 | AE16: =AD16-AC16 -> -18158.446 | AF16: =IFERROR(K16/H16,0) -> 0.15770609 | AG16: =IFERROR((K16-AB16-AC16)/H16,0) -> 0.064086022 | AI16: 55 | AJ16: Cheapest entry. Shorewalk rental pool may be underwritten as condotel/non-warrantable (75% LTV, fewer lenders). | AK16: Zillow
A17: 12 | B17: 539 Forest Way (Cedars East, LBK) | C17: Longboat Key 34228 | D17: Sarasota | E17: Townhome | F17: 2/2.5 / 1,440 / 1990 | G17: 639000 | H17: 639000 | I17: 0 | J17: =Assumptions!$C$15 -> 0.25 | K17: 50000 | L17: "~$50,000 average annual rental payout revenue, after Airbnb and VRBO fees" | M17: AE | N17: N | O17: 945 | Q17: STR | R17: =H17*(1-J17) -> 479250 | S17: =IF((1-J17)>0.75,Assumptions!$C$11,IF((1-J17)>0.7,Assumptions!$C$12,Assumptions!$C$13)) -> 0.0725 | T17: =PMT(S17/12,Assumptions!$C$14,-R17) -> 3269.3298 | U17: =H17*INDEX(Assumptions!$C$28:$C$34,MATCH(D17,Assumptions!$B$28:$B$34,0))/12 -> 718.875 | V17: =IF(ISNUMBER(P17),P17,INDEX(Assumptions!$D$28:$D$34,MATCH(D17,Assumptions!$B$28:$B$34,0))+INDEX(Assumptions!$C$22:$C$25,MATCH(M17,Assumptions!$B$22:$B$25,0)))/12 -> 958.33333 | W17: =T17+U17+V17+O17 -> 5891.5382 | X17: =IFERROR(K17/12/W17,0) -> 0.707229 | Y17: =IFERROR(K17*Assumptions!$C$18/12/W17,0) -> 0.5657832 | Z17: =H17*J17+H17*(Assumptions!$C$16-I17) -> 185310 | AA17: =W17*Assumptions!$C$17 -> 35349.229 | AB17: =K17*INDEX(Assumptions!$H$37:$H$38,MATCH(Q17,Assumptions!$B$37:$B$38,0))+Assumptions!$C$41+IF(N17="Y",Assumptions!$C$42,Assumptions!$C$43) -> 18700 | AC17: =K17*INDEX(Assumptions!$C$37:$C$38,MATCH(Q17,Assumptions!$B$37:$B$38,0)) -> 10000 | AD17: =K17-AB17-W17*12 -> -39398.458 | AE17: =AD17-AC17 -> -49398.458 | AF17: =IFERROR(K17/H17,0) -> 0.078247261 | AG17: =IFERROR((K17-AB17-AC17)/H17,0) -> 0.033333333 | AI17: 27 | AJ17: Shown as a reject example: $945/mo HOA + max 26 rentals/yr kills DSCR. | AK17: Zillow
A20: Operating STRs with no $ in listing: request T12 payouts (could become candidates)
B21: Address | C21: City / ZIP | G21: Price | L21: Evidence (no $ in listing) | AJ21: Ask agent for | AK21: Link
B22: 8403 13th Ave NW | C22: Bradenton 34209 | G22: 619000 | L22: "highly successful, income-generating VRBO"; no rental restrictions; outside flood zone; 147 DOM, 3 cuts | AJ22: T12 payout reports + TDT filings | AK22: Zillow
B23: 926 Plum Tree Ln | C23: Sarasota 34243 (Manatee Co.) | G23: 524900 | L23: "active, successful vacation rental with daily rentals allowed"; no HOA | AJ23: T12 payout reports + TDT filings | AK23: Zillow
B24: 2714 42nd St W | C24: Bradenton 34205 | G24: 499000 | L24: 4BR pool; "currently operating as a successful short-term rental" | AJ24: T12 payout reports + TDT filings | AK24: Zillow
B25: 120 60th St W | C25: Bradenton 34209 | G25: 450000 | L25: "proven rental history available upon request"; 7 price cuts ($549k -> $450k) | AJ25: T12 payout reports + TDT filings | AK25: Zillow
B26: 1214 21st St W | C26: Bradenton 34205 | G26: 625000 | L26: "ESTABLISHED SUCCESSFUL SHORT-TERM RENTAL"; salt pool + spa; impact windows | AJ26: T12 payout reports + TDT filings | AK26: Zillow
B27: 6215 Rodgers Ave | C27: Sarasota 34231 | G27: 419999 | L27: "proven Airbnb performer"; near Siesta; 291 DOM. County 30-day rule applies -> seasonal only | AJ27: T12 payout reports + TDT filings | AK27: Zillow
B28: 1664 Lakeview Pl | C28: Englewood 34223 | G28: 374900 | L28: "proven vacation rental", pool, 1-month minimum (seasonal model) | AJ28: T12 payout reports + TDT filings | AK28: Zillow

Sheet Pinellas
A1: Pinellas County: STR / Seasonal Candidates with Documented Income
A2: Active as of 2026-10-18. Same method: Zillow keyword sweeps with full remarks + jurisdiction rules.
A3: Edit blue cells (Offer Price, Seller Credit %, Down Pmt %, Income, Flood Zone, Ins Override) to rerun. Ins Override (blank = county base + flood) is for condos with master wind/flood policies. Qualify on DSCR (lender haircut) >= 1.00; >= 1.15 preferred. Income is seller-stated until verified with platform payout reports.
A5: Rank | B5: Address | C5: City / ZIP | D5: County | E5: Type | F5: Bd/Ba/SqFt/Yr | G5: List Price | H5: Offer Price | I5: Seller Credit % | J5: Down Pmt % | K5: Stated Gross Income ($/yr) | L5: Income Basis (seller-stated) | M5: Flood Zone | N5: Pool | O5: HOA ($/mo) | P5: Ins Override ($/yr) | Q5: Profile | R5: Loan Amount | S5: Rate | T5: P&I ($/mo) | U5: Taxes ($/mo) | V5: Ins + Flood ($/mo) | W5: PITIA ($/mo) | X5: DSCR (gross) | Y5: DSCR (lender haircut) | Z5: Cash to Close | AA5: Reserves (6 mo) | AB5: Opex excl. Mgmt ($/yr) | AC5: Mgmt ($/yr) | AD5: Cash Flow Self-Managed ($/yr) | AE5: Cash Flow Full PM ($/yr) | AF5: Gross Yield | AG5: Cap Rate (w/ PM) | AH5: Last Sale | AI5: DOM | AJ5: Key Risks / Notes | AK5: Listing Link
A6: 1 | B6: 12565 81st Ave | C6: Seminole 33776 | D6: Pinellas | E6: SFR | F6: 3/2 / 1,306 / 1960 | G6: 499000 | H6: 485000 | I6: 0 | J6: =Assumptions!$C$15 -> 0.25 | K6: 71000 | L6: "approximately $71,000 in estimated annual revenue, 66% average occupancy, $252 ADR"; Airbnb since 2022 | M6: Unknown | N6: Y | O6: 0 | Q6: STR | R6: =H6*(1-J6) -> 363750 | S6: =IF((1-J6)>0.75,Assumptions!$C$11,IF((1-J6)>0.7,Assumptions!$C$12,Assumptions!$C$13)) -> 0.0725 | T6: =PMT(S6/12,Assumptions!$C$14,-R6) -> 2481.4162 | U6: =H6*INDEX(Assumptions!$C$28:$C$34,MATCH(D6,Assumptions!$B$28:$B$34,0))/12 -> 646.66667 | V6: =IF(ISNUMBER(P6),P6,INDEX(Assumptions!$D$28:$D$34,MATCH(D6,Assumptions!$B$28:$B$34,0))+INDEX(Assumptions!$C$22:$C$25,MATCH(M6,Assumptions!$B$22:$B$25,0)))/12 -> 750 | W6: =T6+U6+V6+O6 -> 3878.0829 | X6: =IFERROR(K6/12/W6,0) -> 1.5256679 | Y6: =IFERROR(K6*Assumptions!$C$18/12/W6,0) -> 1.2205343 | Z6: =H6*J6+H6*(Assumptions!$C$16-I6) -> 140650 | AA6: =W6*Assumptions!$C$17 -> 23268.497 | AB6: =K6*INDEX(Assumptions!$H$37:$H$38,MATCH(Q6,Assumptions!$B$37:$B$38,0))+Assumptions!$C$41+IF(N6="Y",Assumptions!$C$42,Assumptions!$C$43) -> 25330 | AC6: =K6*INDEX(Assumptions!$C$37:$C$38,MATCH(Q6,Assumptions!$B$37:$B$38,0)) -> 14200 | AD6: =K6-AB6-W6*12 -> -866.99462 | AE6: =AD6-AC6 -> -15066.995 | AF6: =IFERROR(K6/H6,0) -> 0.14639175 | AG6: =IFERROR((K6-AB6-AC6)/H6,0) -> 0.064886598 | AI6: 29 | AJ6: Heated pool, furnished, 'city-approved STR license' (City of Seminole: confirm rules + transfer). Best Pinellas house found. Inland: ~10-15 min to Madeira/Indian Rocks beaches. | AK6: Zillow
A7: 2 | B7: 4000 46th St N | C7: St Petersburg 33714 | D7: Pinellas | E7: SFR | F7: 4/2 / 1,579 / 1936 | G7: 500000 | H7: 485000 | I7: 0 | J7: =Assumptions!$C$15 -> 0.25 | K7: 85000 | L7: "already on pace to do over $85k of Gross Income in it's first full year as a short term rental" | M7: Unknown | N7: Y | O7: 0 | Q7: STR | R7: =H7*(1-J7) -> 363750 | S7: =IF((1-J7)>0.75,Assumptions!$C$11,IF((1-J7)>0.7,Assumptions!$C$12,Assumptions!$C$13)) -> 0.0725 | T7: =PMT(S7/12,Assumptions!$C$14,-R7) -> 2481.4162 | U7: =H7*INDEX(Assumptions!$C$28:$C$34,MATCH(D7,Assumptions!$B$28:$B$34,0))/12 -> 646.66667 | V7: =IF(ISNUMBER(P7),P7,INDEX(Assumptions!$D$28:$D$34,MATCH(D7,Assumptions!$B$28:$B$34,0))+INDEX(Assumptions!$C$22:$C$25,MATCH(M7,Assumptions!$B$22:$B$25,0)))/12 -> 750 | W7: =T7+U7+V7+O7 -> 3878.0829 | X7: =IFERROR(K7/12/W7,0) -> 1.8265039 | Y7: =IFERROR(K7*Assumptions!$C$18/12/W7,0) -> 1.4612031 | Z7: =H7*J7+H7*(Assumptions!$C$16-I7) -> 140650 | AA7: =W7*Assumptions!$C$17 -> 23268.497 | AB7: =K7*INDEX(Assumptions!$H$37:$H$38,MATCH(Q7,Assumptions!$B$37:$B$38,0))+Assumptions!$C$41+IF(N7="Y",Assumptions!$C$42,Assumptions!$C$43) -> 28550 | AC7: =K7*INDEX(Assumptions!$C$37:$C$38,MATCH(Q7,Assumptions!$B$37:$B$38,0)) -> 17000 | AD7: =K7-AB7-W7*12 -> 9913.0054 | AE7: =AD7-AC7 -> -7086.9946 | AF7: =IFERROR(K7/H7,0) -> 0.17525773 | AG7: =IFERROR((K7-AB7-AC7)/H7,0) -> 0.081340206 | AI7: 18 | AJ7: Heated pool + spa, 4BR. 33714 straddles City of St. Pete (30-day rule) and unincorporated Lealman (legal w/ Certificate of Use): CONFIRM jurisdiction first. 1936 build: insurance. Low current tax will reset. | AK7: Zillow
A8: 3 | B8: 341 Wertz Dr | C8: Largo 33771 | D8: Pinellas | E8: SFR | F8: 3/2 / 1,038 / 1961 | G8: 359000 | H8: 340000 | I8: 0 | J8: =Assumptions!$C$15 -> 0.25 | K8: 51000 | L8: "over $51,000 in revenue in the 12 months leading up to the hurricanes" (pre-Oct 2024) | M8: Unknown | N8: N | O8: 0 | Q8: STR | R8: =H8*(1-J8) -> 255000 | S8: =IF((1-J8)>0.75,Assumptions!$C$11,IF((1-J8)>0.7,Assumptions!$C$12,Assumptions!$C$13)) -> 0.0725 | T8: =PMT(S8/12,Assumptions!$C$14,-R8) -> 1739.5495 | U8: =H8*INDEX(Assumptions!$C$28:$C$34,MATCH(D8,Assumptions!$B$28:$B$34,0))/12 -> 453.33333 | V8: =IF(ISNUMBER(P8),P8,INDEX(Assumptions!$D$28:$D$34,MATCH(D8,Assumptions!$B$28:$B$34,0))+INDEX(Assumptions!$C$22:$C$25,MATCH(M8,Assumptions!$B$22:$B$25,0)))/12 -> 750 | W8: =T8+U8+V8+O8 -> 2942.8828 | X8: =IFERROR(K8/12/W8,0) -> 1.4441621 | Y8: =IFERROR(K8*Assumptions!$C$18/12/W8,0) -> 1.1553297 | Z8: =H8*J8+H8*(Assumptions!$C$16-I8) -> 98600 | AA8: =W8*Assumptions!$C$17 -> 17657.297 | AB8: =K8*INDEX(Assumptions!$H$37:$H$38,MATCH(Q8,Assumptions!$B$37:$B$38,0))+Assumptions!$C$41+IF(N8="Y",Assumptions!$C$42,Assumptions!$C$43) -> 18930 | AC8: =K8*INDEX(Assumptions!$C$37:$C$38,MATCH(Q8,Assumptions!$B$37:$B$38,0)) -> 10200 | AD8: =K8-AB8-W8*12 -> -3244.5942 | AE8: =AD8-AC8 -> -13444.594 | AF8: =IFERROR(K8/H8,0) -> 0.15 | AG8: =IFERROR((K8-AB8-AC8)/H8,0) -> 0.064323529 | AI8: 257 | AJ8: STR paused since 2024 storms (new roof Apr 2025): lender may not accept 2-yr-old history. Largo: STR legal. 257 DOM: negotiable. | AK8: Zillow
A9: 4 | B9: 15305 1st St E #305 (condo) | C9: Madeira Beach 33708 | D9: Pinellas | E9: Condo | F9: 3/3 / 1,440 / 2020 | G9: 659900 | H9: 640000 | I9: 0 | J9: =Assumptions!$C$15 -> 0.25 | K9: 75000 | L9: "$75K in gross rental revenue in 2025 and already over $60K generated year-to-date in 2026" | M9: AE | N9: N | O9: 961 | Q9: STR | R9: =H9*(1-J9) -> 480000 | S9: =IF((1-J9)>0.75,Assumptions!$C$11,IF((1-J9)>0.7,Assumptions!$C$12,Assumptions!$C$13)) -> 0.0725 | T9: =PMT(S9/12,Assumptions!$C$14,-R9) -> 3274.4461 | U9: =H9*INDEX(Assumptions!$C$28:$C$34,MATCH(D9,Assumptions!$B$28:$B$34,0))/12 -> 853.33333 | V9: =IF(ISNUMBER(P9),P9,INDEX(Assumptions!$D$28:$D$34,MATCH(D9,Assumptions!$B$28:$B$34,0))+INDEX(Assumptions!$C$22:$C$25,MATCH(M9,Assumptions!$B$22:$B$25,0)))/12 -> 958.33333 | W9: =T9+U9+V9+O9 -> 6047.1128 | X9: =IFERROR(K9/12/W9,0) -> 1.0335511 | Y9: =IFERROR(K9*Assumptions!$C$18/12/W9,0) -> 0.82684087 | Z9: =H9*J9+H9*(Assumptions!$C$16-I9) -> 185600 | AA9: =W9*Assumptions!$C$17 -> 36282.677 | AB9: =K9*INDEX(Assumptions!$H$37:$H$38,MATCH(Q9,Assumptions!$B$37:$B$38,0))+Assumptions!$C$41+IF(N9="Y",Assumptions!$C$42,Assumptions!$C$43) -> 24450 | AC9: =K9*INDEX(Assumptions!$C$37:$C$38,MATCH(Q9,Assumptions!$B$37:$B$38,0)) -> 15000 | AD9: =K9-AB9-W9*12 -> -22015.354 | AE9: =AD9-AC9 -> -37015.354 | AF9: =IFERROR(K9/H9,0) -> 0.1171875 | AG9: =IFERROR((K9-AB9-AC9)/H9,0) -> 0.055546875 | AI9: 36 | AJ9: Best-documented Pinellas income. 2020 building (lower SB 4-D assessment risk). Confirm Madeira zoning allows <30-day and condo DSCR warrantability. | AK9: Zillow
A10: 5 | B10: 13235 Gulf Blvd #502 (Madeira Bay Resort) | C10: Madeira Beach 33708 | D10: Pinellas | E10: Condo | F10: 2/2 / 734 / 2006 | G10: 575000 | H10: 560000 | I10: 0 | J10: =Assumptions!$C$15 -> 0.25 | K10: 59000 | L10: "Last year's gross rents were $59K" | M10: AE | N10: N | O10: 630 | Q10: STR | R10: =H10*(1-J10) -> 420000 | S10: =IF((1-J10)>0.75,Assumptions!$C$11,IF((1-J10)>0.7,Assumptions!$C$12,Assumptions!$C$13)) -> 0.0725 | T10: =PMT(S10/12,Assumptions!$C$14,-R10) -> 2865.1404 | U10: =H10*INDEX(Assumptions!$C$28:$C$34,MATCH(D10,Assumptions!$B$28:$B$34,0))/12 -> 746.66667 | V10: =IF(ISNUMBER(P10),P10,INDEX(Assumptions!$D$28:$D$34,MATCH(D10,Assumptions!$B$28:$B$34,0))+INDEX(Assumptions!$C$22:$C$25,MATCH(M10,Assumptions!$B$22:$B$25,0)))/12 -> 958.33333 | W10: =T10+U10+V10+O10 -> 5200.1404 | X10: =IFERROR(K10/12/W10,0) -> 0.9454873 | Y10: =IFERROR(K10*Assumptions!$C$18/12/W10,0) -> 0.75638984 | Z10: =H10*J10+H10*(Assumptions!$C$16-I10) -> 162400 | AA10: =W10*Assumptions!$C$17 -> 31200.842 | AB10: =K10*INDEX(Assumptions!$H$37:$H$38,MATCH(Q10,Assumptions!$B$37:$B$38,0))+Assumptions!$C$41+IF(N10="Y",Assumptions!$C$42,Assumptions!$C$43) -> 20770 | AC10: =K10*INDEX(Assumptions!$C$37:$C$38,MATCH(Q10,Assumptions!$B$37:$B$38,0)) -> 11800 | AD10: =K10-AB10-W10*12 -> -24171.685 | AE10: =AD10-AC10 -> -35971.685 | AF10: =IFERROR(K10/H10,0) -> 0.10535714 | AG10: =IFERROR((K10-AB10-AC10)/H10,0) -> 0.047196429 | AI10: 18 | AJ10: Resort with 24/7 guest services = condotel review: most DSCR lenders decline or cap at 60-70% LTV. | AK10: Zillow
A11: 6 | B11: 17960 Gulf Blvd #121 (townhome) | C11: Redington Shores 33708 | D11: Pinellas | E11: Townhome | F11: 2/2.5 / 1,237 / 1989 | G11: 614999 | H11: 590000 | I11: 0 | J11: =Assumptions!$C$15 -> 0.25 | K11: 47890 | L11: "$47,890 IN REVENUE ALREADY BOOKED FOR 2027"; $20k+ Feb-May 2026; 30-day minimum | M11: VE | N11: N | O11: 835 | Q11: Seasonal | R11: =H11*(1-J11) -> 442500 | S11: =IF((1-J11)>0.75,Assumptions!$C$11,IF((1-J11)>0.7,Assumptions!$C$12,Assumptions!$C$13)) -> 0.0725 | T11: =PMT(S11/12,Assumptions!$C$14,-R11) -> 3018.63 | U11: =H11*INDEX(Assumptions!$C$28:$C$34,MATCH(D11,Assumptions!$B$28:$B$34,0))/12 -> 786.66667 | V11: =IF(ISNUMBER(P11),P11,INDEX(Assumptions!$D$28:$D$34,MATCH(D11,Assumptions!$B$28:$B$34,0))+INDEX(Assumptions!$C$22:$C$25,MATCH(M11,Assumptions!$B$22:$B$25,0)))/12 -> 1333.3333 | W11: =T11+U11+V11+O11 -> 5973.63 | X11: =IFERROR(K11/12/W11,0) -> 0.66807507 | Y11: =IFERROR(K11*Assumptions!$C$18/12/W11,0) -> 0.53446006 | Z11: =H11*J11+H11*(Assumptions!$C$16-I11) -> 171100 | AA11: =W11*Assumptions!$C$17 -> 35841.78 | AB11: =K11*INDEX(Assumptions!$H$37:$H$38,MATCH(Q11,Assumptions!$B$37:$B$38,0))+Assumptions!$C$41+IF(N11="Y",Assumptions!$C$42,Assumptions!$C$43) -> 13425.7 | AC11: =K11*INDEX(Assumptions!$C$37:$C$38,MATCH(Q11,Assumptions!$B$37:$B$38,0)) -> 5746.8 | AD11: =K11-AB11-W11*12 -> -37219.26 | AE11: =AD11-AC11 -> -42966.06 | AF11: =IFERROR(K11/H11,0) -> 0.081169492 | AG11: =IFERROR((K11-AB11-AC11)/H11,0) -> 0.048673729 | AI11: 152 | AJ11: Gulf-front, 30-day minimum (seasonal model). VE flood + $835 HOA kill DSCR. | AK11: Zillow
A12: 7 | B12: 1904 Gulf Blvd #D (condo) | C12: Indian Rocks Beach 33785 | D12: Pinellas | E12: Condo | F12: 2/2 / 1,135 / 1997 | G12: 699000 | H12: 699000 | I12: 0 | J12: =Assumptions!$C$15 -> 0.25 | K12: 50000 | L12: "averaged approximately $50,000 annually in gross rental revenue since 2023"; weekly rentals | M12: AE | N12: N | O12: 1325 | Q12: STR | R12: =H12*(1-J12) -> 524250 | S12: =IF((1-J12)>0.75,Assumptions!$C$11,IF((1-J12)>0.7,Assumptions!$C$12,Assumptions!$C$13)) -> 0.0725 | T12: =PMT(S12/12,Assumptions!$C$14,-R12) -> 3576.3091 | U12: =H12*INDEX(Assumptions!$C$28:$C$34,MATCH(D12,Assumptions!$B$28:$B$34,0))/12 -> 932 | V12: =IF(ISNUMBER(P12),P12,INDEX(Assumptions!$D$28:$D$34,MATCH(D12,Assumptions!$B$28:$B$34,0))+INDEX(Assumptions!$C$22:$C$25,MATCH(M12,Assumptions!$B$22:$B$25,0)))/12 -> 958.33333 | W12: =T12+U12+V12+O12 -> 6791.6425 | X12: =IFERROR(K12/12/W12,0) -> 0.61349912 | Y12: =IFERROR(K12*Assumptions!$C$18/12/W12,0) -> 0.49079929 | Z12: =H12*J12+H12*(Assumptions!$C$16-I12) -> 202710 | AA12: =W12*Assumptions!$C$17 -> 40749.855 | AB12: =K12*INDEX(Assumptions!$H$37:$H$38,MATCH(Q12,Assumptions!$B$37:$B$38,0))+Assumptions!$C$41+IF(N12="Y",Assumptions!$C$42,Assumptions!$C$43) -> 18700 | AC12: =K12*INDEX(Assumptions!$C$37:$C$38,MATCH(Q12,Assumptions!$B$37:$B$38,0)) -> 10000 | AD12: =K12-AB12-W12*12 -> -50199.71 | AE12: =AD12-AC12 -> -60199.71 | AF12: =IFERROR(K12/H12,0) -> 0.071530758 | AG12: =IFERROR((K12-AB12-AC12)/H12,0) -> 0.030472103 | AI12: 7 | AJ12: Shown as a reject example: $1,325/mo HOA. | AK12: Zillow
A15: Pinellas operating STRs with history on request (legal zones): request T12 payouts + Certificate of Use
B16: Address | C16: City / ZIP | G16: Price | L16: Evidence (no $ in listing) | AJ16: Ask agent for | AK16: Link
B17: 9542 Oakhurst Rd | C17: Seminole 33776 (unincorporated) | G17: 699000 | L17: 4/3 heated pool; "no length and duration limits"; 3 yrs Airbnb/VRBO history on request; STR insurance quote $4,353 | AJ17: T12 payout reports + TDT filings | AK17: Zillow
B18: 6400 Pelican Dr S | C18: St Petersburg 33707 (outside city limits) | G18: 629000 | L18: 3/2 heated pool; "STR history and revenue information available upon request"; 122 DOM | AJ18: T12 payout reports + TDT filings | AK18: Zillow
B19: 7957 Cottonwoode Dr | C19: Largo 33773 | G19: 575000 | L19: 3/2 pool; "documented Airbnb performance and booking history available" | AJ19: T12 payout reports + TDT filings | AK19: Zillow
B20: 8253 137th Ln | C20: Seminole 33776 (unincorporated) | G20: 599000 | L20: 3/2 pool; Airbnb past year with strong performance | AJ20: T12 payout reports + TDT filings | AK20: Zillow
B21: 4986 Woodland Dr | C21: St Petersburg 33708 | G21: 550000 | L21: 2/2 pool; "ACTIVE Short-Term RENTAL"; "NO RENTAL RESTRICTIONS" (verify jurisdiction) | AJ21: T12 payout reports + TDT filings | AK21: Zillow
B22: 9370 83rd St | C22: Seminole 33777 | G22: 425000 | L22: 3/2 pool; operating furnished Airbnb; furniture extra | AJ22: T12 payout reports + TDT filings | AK22: Zillow
B23: 166 Pinellas Way N | C23: St Petersburg 33710 | G23: 550000 | L23: Pool + spa; history on request. Likely City of St. Pete (30-day rule): verify before pursuing | AJ23: T12 payout reports + TDT filings | AK23: Zillow
B24: 14626 Wildwood Dr | C24: Largo 33774 (unincorporated) | G24: 524900 | L24: 4/2 pool; "Currently operating as an AIRBNB" | AJ24: T12 payout reports + TDT filings | AK24: Zillow
B25: 1600 Loretta Ave NW | C25: Largo 33770 | G25: 490000 | L25: 3/2 heated pool + spa, furnished; "registered with the city of Largo as a short term rental" | AJ25: T12 payout reports + TDT filings | AK25: Zillow
B26: 863 Bay Breeze Ter | C26: Largo 33770 | G26: 585000 | L26: 3/2 pool; "INCOME-PRODUCING VRBO"; "NO RENTAL RESTRICTIONS" | AJ26: T12 payout reports + TDT filings | AK26: Zillow
B27: 8628 Magnolia Dr | C27: Seminole 33777 | G27: 520000 | L27: 4/2 pool; "currently operating as a short-term rental"; verify license transferability | AJ27: T12 payout reports + TDT filings | AK27: Zillow
B28: 839 3rd St N | C28: Safety Harbor 34695 | G28: 499900 | L28: 8-yr vacation rental, hundreds of 5-star reviews; "detailed financials are available on request"; 2/2 small | AJ28: T12 payout reports + TDT filings | AK28: Zillow
... B30: 414 Tampa Rd (Ozona) | C30: Palm Harbor 34683 | G30: 349900 | L30: 2020-2026 rental history + 2027 bookings on request; listing gives $46k projection (not actual) | AJ30: T12 payout reports + TDT filings | AK30: Zillow

Sheet Other SWFL Listings
A1: Lee / Charlotte / Collier: Listings with Stated Rental Income
A2: Active as of 2026-10-18. 3 Zillow sweeps (~257 unique listings) before the Apify usage cap; documented income is thin outside Cape Coral. See 'Other SWFL Markets' for the market ranking.
A3: Edit blue cells (Offer Price, Seller Credit %, Down Pmt %, Income, Flood Zone, Ins Override) to rerun. Ins Override (blank = county base + flood) is for condos with master wind/flood policies. Qualify on DSCR (lender haircut) >= 1.00; >= 1.15 preferred. Income is seller-stated until verified with platform payout reports.
A5: Rank | B5: Address | C5: City / ZIP | D5: County | E5: Type | F5: Bd/Ba/SqFt/Yr | G5: List Price | H5: Offer Price | I5: Seller Credit % | J5: Down Pmt % | K5: Stated Gross Income ($/yr) | L5: Income Basis (seller-stated) | M5: Flood Zone | N5: Pool | O5: HOA ($/mo) | P5: Ins Override ($/yr) | Q5: Profile | R5: Loan Amount | S5: Rate | T5: P&I ($/mo) | U5: Taxes ($/mo) | V5: Ins + Flood ($/mo) | W5: PITIA ($/mo) | X5: DSCR (gross) | Y5: DSCR (lender haircut) | Z5: Cash to Close | AA5: Reserves (6 mo) | AB5: Opex excl. Mgmt ($/yr) | AC5: Mgmt ($/yr) | AD5: Cash Flow Self-Managed ($/yr) | AE5: Cash Flow Full PM ($/yr) | AF5: Gross Yield | AG5: Cap Rate (w/ PM) | AH5: Last Sale | AI5: DOM | AJ5: Key Risks / Notes | AK5: Listing Link
A6: 1 | B6: 326 NW 21st Ter | C6: Cape Coral 33993 | D6: Lee | E6: SFR | F6: 3/2 / 1,734 / 2023 | G6: 475000 | H6: 460000 | I6: 0 | J6: =Assumptions!$C$15 -> 0.25 | K6: 60000 | L6: "generated over $60,000 in annual rental revenue" | M6: Unknown | N6: Y | O6: 0 | Q6: STR | R6: =H6*(1-J6) -> 345000 | S6: =IF((1-J6)>0.75,Assumptions!$C$11,IF((1-J6)>0.7,Assumptions!$C$12,Assumptions!$C$13)) -> 0.0725 | T6: =PMT(S6/12,Assumptions!$C$14,-R6) -> 2353.5082 | U6: =H6*INDEX(Assumptions!$C$28:$C$34,MATCH(D6,Assumptions!$B$28:$B$34,0))/12 -> 651.66667 | V6: =IF(ISNUMBER(P6),P6,INDEX(Assumptions!$D$28:$D$34,MATCH(D6,Assumptions!$B$28:$B$34,0))+INDEX(Assumptions!$C$22:$C$25,MATCH(M6,Assumptions!$B$22:$B$25,0)))/12 -> 750 | W6: =T6+U6+V6+O6 -> 3755.1748 | X6: =IFERROR(K6/12/W6,0) -> 1.3314959 | Y6: =IFERROR(K6*Assumptions!$C$18/12/W6,0) -> 1.0651967 | Z6: =H6*J6+H6*(Assumptions!$C$16-I6) -> 133400 | AA6: =W6*Assumptions!$C$17 -> 22531.049 | AB6: =K6*INDEX(Assumptions!$H$37:$H$38,MATCH(Q6,Assumptions!$B$37:$B$38,0))+Assumptions!$C$41+IF(N6="Y",Assumptions!$C$42,Assumptions!$C$43) -> 22800 | AC6: =K6*INDEX(Assumptions!$C$37:$C$38,MATCH(Q6,Assumptions!$B$37:$B$38,0)) -> 12000 | AD6: =K6-AB6-W6*12 -> -7862.098 | AE6: =AD6-AC6 -> -19862.098 | AF6: =IFERROR(K6/H6,0) -> 0.13043478 | AG6: =IFERROR((K6-AB6-AC6)/H6,0) -> 0.054782609 | AI6: 14 | AJ6: Only SWFL listing clearing DSCR after haircut. NW Cape = inland, ~30+ min to beach. Check North Cape utility assessment (~$32k/lot, ~$3.4k/yr). Cape Coral STR registration $350/yr. | AK6: Zillow
A7: 2 | B7: 370 Townhouse Ln #65 (North Captiva) | C7: Captiva 33924 | D7: Lee | E7: Townhome | F7: 3/2 / 979 / 1985 | G7: 589900 | H7: 589900 | I7: 0 | J7: =Assumptions!$C$15 -> 0.25 | K7: 60000 | L7: "established in a successful vacation rental program with $60,000+ in annual rental income" | M7: AE | N7: N | O7: 583 | Q7: STR | R7: =H7*(1-J7) -> 442425 | S7: =IF((1-J7)>0.75,Assumptions!$C$11,IF((1-J7)>0.7,Assumptions!$C$12,Assumptions!$C$13)) -> 0.0725 | T7: =PMT(S7/12,Assumptions!$C$14,-R7) -> 3018.1184 | U7: =H7*INDEX(Assumptions!$C$28:$C$34,MATCH(D7,Assumptions!$B$28:$B$34,0))/12 -> 835.69167 | V7: =IF(ISNUMBER(P7),P7,INDEX(Assumptions!$D$28:$D$34,MATCH(D7,Assumptions!$B$28:$B$34,0))+INDEX(Assumptions!$C$22:$C$25,MATCH(M7,Assumptions!$B$22:$B$25,0)))/12 -> 958.33333 | W7: =T7+U7+V7+O7 -> 5395.1434 | X7: =IFERROR(K7/12/W7,0) -> 0.92675942 | Y7: =IFERROR(K7*Assumptions!$C$18/12/W7,0) -> 0.74140754 | Z7: =H7*J7+H7*(Assumptions!$C$16-I7) -> 171071 | AA7: =W7*Assumptions!$C$17 -> 32370.86 | AB7: =K7*INDEX(Assumptions!$H$37:$H$38,MATCH(Q7,Assumptions!$B$37:$B$38,0))+Assumptions!$C$41+IF(N7="Y",Assumptions!$C$42,Assumptions!$C$43) -> 21000 | AC7: =K7*INDEX(Assumptions!$C$37:$C$38,MATCH(Q7,Assumptions!$B$37:$B$38,0)) -> 12000 | AD7: =K7-AB7-W7*12 -> -25741.721 | AE7: =AD7-AC7 -> -37741.721 | AF7: =IFERROR(K7/H7,0) -> 0.10171215 | AG7: =IFERROR((K7-AB7-AC7)/H7,0) -> 0.04577047 | AI7: 23 | AJ7: Boat-access-only island: financing/insurance hard. Rental program = condotel-style review. | AK7: Zillow
A8: 3 | B8: 10345 Longshore Rd #31 | C8: Placida 33946 | D8: Charlotte | E8: Townhome | F8: 3/3 / 2,416 / 2020 | G8: 530000 | H8: 530000 | I8: 0 | J8: =Assumptions!$C$15 -> 0.25 | K8: 29250 | L8: "annual short term rental with same family 12/1-4/15 generating rental income of $29,250" | M8: Unknown | N8: N | O8: 520 | Q8: Seasonal | R8: =H8*(1-J8) -> 397500 | S8: =IF((1-J8)>0.75,Assumptions!$C$11,IF((1-J8)>0.7,Assumptions!$C$12,Assumptions!$C$13)) -> 0.0725 | T8: =PMT(S8/12,Assumptions!$C$14,-R8) -> 2711.6507 | U8: =H8*INDEX(Assumptions!$C$28:$C$34,MATCH(D8,Assumptions!$B$28:$B$34,0))/12 -> 728.75 | V8: =IF(ISNUMBER(P8),P8,INDEX(Assumptions!$D$28:$D$34,MATCH(D8,Assumptions!$B$28:$B$34,0))+INDEX(Assumptions!$C$22:$C$25,MATCH(M8,Assumptions!$B$22:$B$25,0)))/12 -> 750 | W8: =T8+U8+V8+O8 -> 4710.4007 | X8: =IFERROR(K8/12/W8,0) -> 0.5174719 | Y8: =IFERROR(K8*Assumptions!$C$18/12/W8,0) -> 0.41397752 | Z8: =H8*J8+H8*(Assumptions!$C$16-I8) -> 153700 | AA8: =W8*Assumptions!$C$17 -> 28262.404 | AB8: =K8*INDEX(Assumptions!$H$37:$H$38,MATCH(Q8,Assumptions!$B$37:$B$38,0))+Assumptions!$C$41+IF(N8="Y",Assumptions!$C$42,Assumptions!$C$43) -> 11002.5 | AC8: =K8*INDEX(Assumptions!$C$37:$C$38,MATCH(Q8,Assumptions!$B$37:$B$38,0)) -> 3510 | AD8: =K8-AB8-W8*12 -> -38277.309 | AE8: =AD8-AC8 -> -41787.309 | AF8: =IFERROR(K8/H8,0) -> 0.055188679 | AG8: =IFERROR((K8-AB8-AC8)/H8,0) -> 0.027806604 | AI8: 126 | AJ8: One seasonal tenant only; rest of year unbooked. Shown as a weak example. | AK8: Zillow
A11: Operating STRs with history on request: Cape Coral Gulf-access + Charlotte Harbor (request T12)
B12: Address | C12: City / ZIP | G12: Price | L12: Evidence (no $ in listing) | AJ12: Ask agent for | AK12: Link
B13: 930 SW 37th Ter (PropertyRadar find) | C13: Cape Coral 33914 | G13: 400000 | L13: 2024 remarks: 'successful vacation rental'; on FL DBPR vacation-rental license list; 3/2 heated pool + spa, 2008, zone X, ~400 DOM. Not Gulf access. Needs ~$49k gross for DSCR 1.00 at list, 25% down. | AJ13: T12 payouts + license status; why it didn't sell at $400k | AK13: Redfin
B14: 2712 SW 4th Pl | C14: Cape Coral 33914 | G14: 599000 | L14: Pool, 2020 build; Feb 1-Mar 31 2027 booking (59 nights) + Nov 2026 booking transfer | AJ14: T12 payout reports + TDT filings | AK14: Zillow
B15: 1433 SE 28th Ter | C15: Cape Coral 33904 | G15: 542500 | L15: Airbnb Guest Favorite 4.93 stars; Gulf access; solar-heated pool | AJ15: T12 payout reports + TDT filings | AK15: Zillow
B16: 4928 SW 1st Ct | C16: Cape Coral 33914 | G16: 599900 | L16: "proven income stream through Airbnb and VRBO"; direct Gulf access; 2BR; 424 DOM | AJ16: T12 payout reports + TDT filings | AK16: Zillow
B17: 2917 SW Santa Barbara Pl (duplex) | C17: Cape Coral 33914 | G17: 659900 | L17: 2024 duplex, 2x 3/2+den, "PROVEN AIRBNB RENTAL HISTORY", Guest Favorite; motivated seller | AJ17: T12 payout reports + TDT filings | AK17: Zillow
B18: 3106 SE 8th Pl | C18: Cape Coral 33904 | G18: 390000 | L18: Pool, furnished, future rentals in place | AJ18: T12 payout reports + TDT filings | AK18: Zillow
B19: 1768 Whiskey Creek Dr | C19: Fort Myers 33919 | G19: 599000 | L19: "rental income information available upon request"; seller offering rate buydown | AJ19: T12 payout reports + TDT filings | AK19: Zillow
B20: 951 Lassino Ct | C20: Punta Gorda 33950 | G20: 659000 | L20: Punta Gorda Isles pool home; ~2 yrs history, reviews and accounts may transfer; check deed restrictions | AJ20: T12 payout reports + TDT filings | AK20: Zillow
B21: 9277 Saint Catherine Ave | C21: Englewood 34224 (Charlotte) | G21: 449900 | L21: Pool, furnished; spring reservations may transfer; ~6 mi to beach | AJ21: T12 payout reports + TDT filings | AK21: Zillow
B22: 59 Wickliffe Dr | C22: Naples 34110 | G22: 665000 | L22: "$29k in future bookings on Airbnb" (forward only); unincorporated Collier | AJ22: T12 payout reports + TDT filings | AK22: Zillow

Sheet Monroe (Keys)
A1: Monroe County (Florida Keys): Licensed Rentals with Stated Income
A2: As of 2026-10-18. Web-search sweep only (Zillow scraper capped): ~85 searches across Zillow/Redfin/brokerage IDX snippets. Under $950k, documented-income inventory is almost entirely condos in a few STR-legal complexes.
A3: Edit blue cells (Offer Price, Seller Credit %, Down Pmt %, Income, Flood Zone, Ins Override) to rerun. Ins Override (blank = county base + flood) is for condos with master wind/flood policies. Qualify on DSCR (lender haircut) >= 1.00; >= 1.15 preferred. Income is seller-stated until verified with platform payout reports.
A5: Rank | B5: Address | C5: City / ZIP | D5: County | E5: Type | F5: Bd/Ba/SqFt/Yr | G5: List Price | H5: Offer Price | I5: Seller Credit % | J5: Down Pmt % | K5: Stated Gross Income ($/yr) | L5: Income Basis (seller-stated) | M5: Flood Zone | N5: Pool | O5: HOA ($/mo) | P5: Ins Override ($/yr) | Q5: Profile | R5: Loan Amount | S5: Rate | T5: P&I ($/mo) | U5: Taxes ($/mo) | V5: Ins + Flood ($/mo) | W5: PITIA ($/mo) | X5: DSCR (gross) | Y5: DSCR (lender haircut) | Z5: Cash to Close | AA5: Reserves (6 mo) | AB5: Opex excl. Mgmt ($/yr) | AC5: Mgmt ($/yr) | AD5: Cash Flow Self-Managed ($/yr) | AE5: Cash Flow Full PM ($/yr) | AF5: Gross Yield | AG5: Cap Rate (w/ PM) | AH5: Last Sale | AI5: DOM | AJ5: Key Risks / Notes | AK5: Listing Link
